Workbook

Sheet InpC
F6: Constant | G6: Unit | H6: Total
A7: TIMELINE
B9: Model Start
E10: Model Start Date | F10: =J10 -> 45658 | G10: Date | J10: 45658
B12: Actuals
E13: Actual Start Date | F13: =J13 -> 45658 | G13: Date | J13: 45658
E14: Actual End Date | F14: =J14 -> 46022 | G14: Date | J14: 46022
B16: Projections
E17: Projection Start Date | F17: =J17 -> 46023 | G17: Date | J17: =J14 + 1 -> 46023
E18: Projection End Date | F18: =J18 -> 47848 | G18: Date | J18: 47848
A20: OPERATIONS
B22: Alpha Manufacturers Ltd
E23: Revenue | F23: =J23 -> 5000 | G23: INR Crs | J23: 5000
E24: Revenue Growth Rate | F24: =J24 -> 0.08 | G24: % | J24: 0.08
E25: EBITDA Margin | F25: =J25 -> 0.22 | G25: % | J25: 0.22
E26: Depreciation | F26: =J26 -> 0.03 | G26: % of Revenue | J26: 0.03
E27: Interest Rate | F27: =J27 -> 0.1 | G27: % | J27: 0.1
E28: Corporate Tax Rate | F28: =J28 -> 0.25 | G28: % | J28: 0.25
E29: Capital Expenditure | F29: =J29 -> 0.08 | G29: % of Revenue | J29: 0.08
E30: Pre- Transaction Shares Oustanding | F30: =J30 -> 100 | G30: Crores | J30: 100
C32: Balance Sheet Inputs
E33: Fixed Assets | F33: =J33 -> 2500 | G33: INR Crs | J33: 2500
E34: Working Capital | F34: =J34 -> 1300 | G34: INR Crs | J34: 1300
E35: Cash | F35: =J35 -> 400 | G35: INR Crs | J35: 400
E36: Total Assets | F36: =J36 -> 4200 | G36: INR Crs | J36: =SUM(J33:J35) -> 4200
E38: Equity (Net Worth) | F38: =J38 -> 2200 | G38: INR Crs | J38: 2200
E39: Long-term Debt | F39: =J39 -> 1000 | G39: INR Crs | J39: 1000
E40: Other Liabilities | F40: =J40 -> 1000 | G40: INR Crs | J40: 1000
E41: Total Liabilities | F41: =J41 -> 4200 | G41: INR Crs | J41: =SUM(J38:J40) -> 4200
B43: Beta Componenets Pvt. Ltd.
E44: Revenue | F44: =J44 -> 1200 | G44: INR Crs | J44: 1200
E45: Revenue Growth Rate | F45: =J45 -> 0.1 | G45: % | J45: 0.1
E46: Depreciation | F46: =J46 -> 0.05 | G46: % of Revenue | J46: 0.05
E47: Interest Rate | F47: =J47 -> 0.11 | G47: % | J47: 0.11
E48: Corporate Tax Rate | F48: =J48 -> 0.25 | G48: % | J48: 0.25
E49: Capital Expenditure | F49: =J49 -> 0.1 | G49: % of Revenue | J49: 0.1
E50: WACC | F50: =J50 -> 0.12 | G50: % | J50: 0.12
E51: Terminal Growth Rate | F51: =J51 -> 0.04 | G51: % | J51: 0.04
C53: Balance Sheet Inputs
E54: Fixed Assets | F54: =J54 -> 950 | G54: INR Crs | J54: 950
...

Sheet InpS
F6: Constant | G6: Unit | H6: Total

Sheet Alpha
E1: =E$13 -> Period Start | F1: =F$13 -> 0 | G1: =G$13 -> Date | H1: =H$13 -> 0 | I1: =I$13 -> 0 | J1: =J$13 -> 45658 | K1: =K$13 -> 46023 | L1: =L$13 -> 46388 | ... O1: =O$13 -> 47484
E2: =E$14 -> Period End | F2: =F$14 -> 0 | G2: =G$14 -> Date | H2: =H$14 -> 0 | I2: =I$14 -> 0 | J2: =J$14 -> 46022 | K2: =K$14 -> 46387 | L2: =L$14 -> 46752 | ... O2: =O$14 -> 47848
E3: =E$15 -> Number of Days | F3: =F$15 -> 0 | G3: =G$15 -> Days | H3: =H$15 -> 0 | I3: =I$15 -> 0 | J3: =J$15 -> 365 | K3: =K$15 -> 365 | L3: =L$15 -> 365 | ... O3: =O$15 -> 365
E4: =E$16 -> Financial Year | F4: =F$16 -> 0 | G4: =G$16 -> Year | H4: =H$16 -> 0 | I4: =I$16 -> 0 | J4: =J$16 -> 2025 | K4: =K$16 -> 2026 | L4: =L$16 -> 2027 | ... O4: =O$16 -> 2030
F6: Constant | G6: Unit | H6: Total
A7: TIMELINE
E9: Model Counter | G9: Counter | J9: =I9+ 1 -> 1 | K9: =J9+ 1 -> 2 | L9: =K9+ 1 -> 3 | M9: =L9+ 1 -> 4 | N9: =M9+ 1 -> 5 | O9: =N9+ 1 -> 6
E11: =InpC!E$10 -> Model Start Date | F11: =InpC!F$10 -> 45658 | G11: =InpC!G$10 -> Date
E13: Period Start | G13: Date | J13: =IF(J9 = 1, $F11, I14 + 1) -> 45658 | K13: =IF(K9 = 1, $F11, J14 + 1) -> 46023 | L13: =IF(L9 = 1, $F11, K14 + 1) -> 46388 | M13: =IF(M9 = 1, $F11, L14 + 1) -> 46753 | N13: =IF(N9 = 1, $F11, M14 + 1) -> 47119 | O13: =IF(O9 = 1, $F11, N14 + 1) -> 47484
E14: Period End | G14: Date | J14: =EOMONTH(J13, 11) -> 46022 | K14: =EOMONTH(K13, 11) -> 46387 | L14: =EOMONTH(L13, 11) -> 46752 | M14: =EOMONTH(M13, 11) -> 47118 | N14: =EOMONTH(N13, 11) -> 47483 | O14: =EOMONTH(O13, 11) -> 47848
E15: Number of Days | G15: Days | J15: =_xlfn.DAYS(J14, J13 ) + 1 -> 365 | K15: =_xlfn.DAYS(K14, K13 ) + 1 -> 365 | L15: =_xlfn.DAYS(L14, L13 ) + 1 -> 365 | M15: =_xlfn.DAYS(M14, M13 ) + 1 -> 366 | N15: =_xlfn.DAYS(N14, N13 ) + 1 -> 365 | O15: =_xlfn.DAYS(O14, O13 ) + 1 -> 365
E16: Financial Year | G16: Year | J16: =YEAR(J14) -> 2025 | K16: =YEAR(K14) -> 2026 | L16: =YEAR(L14) -> 2027 | M16: =YEAR(M14) -> 2028 | N16: =YEAR(N14) -> 2029 | O16: =YEAR(O14) -> 2030
B18: Actuals
E19: =InpC!E$13 -> Actual Start Date | F19: =InpC!F$13 -> 45658 | G19: =InpC!G$13 -> Date
E20: =InpC!E$14 -> Actual End Date | F20: =InpC!F$14 -> 46022 | G20: =InpC!G$14 -> Date
E21: Actuals Start | G21: Flag | H21: =SUM(J21:O21) -> 1 | J21: =IF(AND($F19>=J$13, $F19<=J$14), 1, 0) -> 1 | K21: =IF(AND($F19>=K$13, $F19<=K$14), 1, 0) -> 0 | L21: =IF(AND($F19>=L$13, $F19<=L$14), 1, 0) -> 0 | M21: =IF(AND($F19>=M$13, $F19<=M$14), 1, 0) -> 0 | N21: =IF(AND($F19>=N$13, $F19<=N$14), 1, 0) -> 0 | O21: =IF(AND($F19>=O$13, $F19<=O$14), 1, 0) -> 0
E22: Actuals End | G22: Flag | H22: =SUM(J22:O22) -> 1 | J22: =IF(AND($F20>=J$13, $F20<=J$14), 1, 0) -> 1 | K22: =IF(AND($F20>=K$13, $F20<=K$14), 1, 0) -> 0 | L22: =IF(AND($F20>=L$13, $F20<=L$14), 1, 0) -> 0 | M22: =IF(AND($F20>=M$13, $F20<=M$14), 1, 0) -> 0 | N22: =IF(AND($F20>=N$13, $F20<=N$14), 1, 0) -> 0 | O22: =IF(AND($F20>=O$13, $F20<=O$14), 1, 0) -> 0
E23: Actuals Active | G23: Flag | H23: =SUM(J23:O23) -> 1 | J23: =J21 +I23 - I22 -> 1 | K23: =K21 +J23 - J22 -> 0 | L23: =L21 +K23 - K22 -> 0 | M23: =M21 +L23 - L22 -> 0 | N23: =N21 +M23 - M22 -> 0 | O23: =O21 +N23 - N22 -> 0
B25: Projections
E26: =InpC!E$17 -> Projection Start Date | F26: =InpC!F$17 -> 46023 | G26: =InpC!G$17 -> Date
E27: =InpC!E$18 -> Projection End Date | F27: =InpC!F$18 -> 47848 | G27: =InpC!G$18 -> Date
E28: Projections Start | G28: Flag | H28: =SUM(J28:O28) -> 1 | J28: =IF(AND($F26>=J$13, $F26<=J$14), 1, 0) -> 0 | K28: =IF(AND($F26>=K$13, $F26<=K$14), 1, 0) -> 1 | L28: =IF(AND($F26>=L$13, $F26<=L$14), 1, 0) -> 0 | M28: =IF(AND($F26>=M$13, $F26<=M$14), 1, 0) -> 0 | N28: =IF(AND($F26>=N$13, $F26<=N$14), 1, 0) -> 0 | O28: =IF(AND($F26>=O$13, $F26<=O$14), 1, 0) -> 0
E29: Projections End | G29: Flag | H29: =SUM(J29:O29) -> 1 | J29: =IF(AND($F27>=J$13, $F27<=J$14), 1, 0) -> 0 | K29: =IF(AND($F27>=K$13, $F27<=K$14), 1, 0) -> 0 | L29: =IF(AND($F27>=L$13, $F27<=L$14), 1, 0) -> 0 | M29: =IF(AND($F27>=M$13, $F27<=M$14), 1, 0) -> 0 | N29: =IF(AND($F27>=N$13, $F27<=N$14), 1, 0) -> 0 | O29: =IF(AND($F27>=O$13, $F27<=O$14), 1, 0) -> 1
E30: Projections Active | G30: Flag | H30: =SUM(J30:O30) -> 5 | J30: =J28 +I30 - I29 -> 0 | K30: =K28 +J30 - J29 -> 1 | L30: =L28 +K30 - K29 -> 1 | M30: =M28 +L30 - L29 -> 1 | N30: =N28 +M30 - M29 -> 1 | O30: =O28 +N30 - N29 -> 1
A32: FINANCIAL STATEMENTS
B34: Income Statement
E35: =E$89 -> Revenue | F35: =F$89 -> 0 | G35: =G$89 -> INR Crs | H35: =H$89 -> 0 | I35: =I$89 -> 0 | J35: =J$89 -> 5000 | K35: =K$89 -> 5400 | L35: =L$89 -> 5832 | ... O35: =O$89 -> 7346.6404
E36: Operating Expenses | G36: INR Crs | J36: =J35 - J37 -> 3900 | K36: =K35 - K37 -> 4212 | L36: =L35 - L37 -> 4548.96 | M36: =M35 - M37 -> 4912.8768 | N36: =N35 - N37 -> 5305.9069 | O36: =O35 - O37 -> 5730.3795
E37: =E$95 -> EBITDA | F37: =F$95 -> 0 | G37: =G$95 -> INR Crs | H37: =H$95 -> 0 | I37: =I$95 -> 0 | J37: =J$95 -> 1100 | K37: =K$95 -> 1188 | L37: =L$95 -> 1283.04 | ... O37: =O$95 -> 1616.2609
E39: =E$100 -> Depreciation | F39: =F$100 -> 0 | G39: =G$100 -> INR Crs | H39: =H$100 -> 0 | I39: =I$100 -> 0 | J39: =J$100 -> 150 | K39: =K$100 -> 162 | L39: =L$100 -> 174.96 | ... O39: =O$100 -> 220.39921
E40: EBIT | G40: INR Crs | J40: =J37 - J39 -> 950 | K40: =K37 - K39 -> 1026 | L40: =L37 - L39 -> 1108.08 | M40: =M37 - M39 -> 1196.7264 | N40: =N37 - N39 -> 1292.4645 | O40: =O37 - O39 -> 1395.8617
E42: =E$114 -> Interest Expense | F42: =F$114 -> 0 | G42: =G$114 -> INR Crs | H42: =H$114 -> 0 | I42: =I$114 -> 0 | J42: =J$114 -> 0 | K42: =K$114 -> 100 | L42: =L$114 -> 100 | ... O42: =O$114 -> 100
E43: Profit Before Tax | G43: INR Crs | J43: =J40 - J42 -> 950 | K43: =K40 - K42 -> 926 | L43: =L40 - L42 -> 1008.08 | M43: =M40 - M42 -> 1096.7264 | N43: =N40 - N42 -> 1192.4645 | O43: =O40 - O42 -> 1295.8617
E45: =E$120 -> Tax Expense | F45: =F$120 -> 0 | G45: =G$120 -> INR Crs | H45: =H$120 -> 0 | I45: =I$120 -> 0 | J45: 300 | K45: =K$120 -> 231.5 | L45: =L$120 -> 252.02 | M45: =M$120 -> 274.1816 | N45: =N$120 -> 298.11613 | O45: =O$120 -> 323.96542
E46: Profit After Tax | G46: INR Crs | J46: =J43 - J45 -> 650 | K46: =K43 - K45 -> 694.5 | L46: =L43 - L45 -> 756.06 | M46: =M43 - M45 -> 822.5448 | N46: =N43 - N45 -> 894.34838 | O46: =O43 - O45 -> 971.89625
E48: Shares Outstanding | G48: Crores | J48: =InpC!$F$30 -> 100 | K48: =InpC!$F$30 -> 100 | L48: =InpC!$F$30 -> 100 | M48: =InpC!$F$30 -> 100 | N48: =InpC!$F$30 -> 100 | O48: =InpC!$F$30 -> 100
E49: Earnings Per Share | G49: INR | J49: =J46/ J48 -> 6.5 | K49: =K46/ K48 -> 6.945 | L49: =L46/ L48 -> 7.5606 | M49: =M46/ M48 -> 8.225448 | N49: =N46/ N48 -> 8.9434838 | O49: =O46/ O48 -> 9.7189625
B51: Balance Sheet
C52: Assets
E53: Fixed Assets | G53: INR Crs | J53: 2500 | K53: =K$132 -> 2770 | L53: =L$132 -> 3061.6 | M53: =M$132 -> 3376.528 | N53: =N$132 -> 3716.6502 | O53: =O$132 -> 4083.9823
...

Sheet Beta
E1: =E$13 -> Period Start | F1: =F$13 -> 0 | G1: =G$13 -> Date | H1: =H$13 -> 0 | I1: =I$13 -> 0 | J1: =J$13 -> 45658 | K1: =K$13 -> 46023 | L1: =L$13 -> 46388 | ... O1: =O$13 -> 47484
E2: =E$14 -> Period End | F2: =F$14 -> 0 | G2: =G$14 -> Date | H2: =H$14 -> 0 | I2: =I$14 -> 0 | J2: =J$14 -> 46022 | K2: =K$14 -> 46387 | L2: =L$14 -> 46752 | ... O2: =O$14 -> 47848
E3: =E$15 -> Number of Days | F3: =F$15 -> 0 | G3: =G$15 -> Days | H3: =H$15 -> 0 | I3: =I$15 -> 0 | J3: =J$15 -> 365 | K3: =K$15 -> 365 | L3: =L$15 -> 365 | ... O3: =O$15 -> 365
E4: =E$16 -> Financial Year | F4: =F$16 -> 0 | G4: =G$16 -> Year | H4: =H$16 -> 0 | I4: =I$16 -> 0 | J4: =J$16 -> 2025 | K4: =K$16 -> 2026 | L4: =L$16 -> 2027 | ... O4: =O$16 -> 2030
F6: Constant | G6: Unit | H6: Total
A7: TIMELINE
E9: Model Counter | G9: Counter | J9: =I9+ 1 -> 1 | K9: =J9+ 1 -> 2 | L9: =K9+ 1 -> 3 | M9: =L9+ 1 -> 4 | N9: =M9+ 1 -> 5 | O9: =N9+ 1 -> 6
E11: =InpC!E$10 -> Model Start Date | F11: =InpC!F$10 -> 45658 | G11: =InpC!G$10 -> Date
E13: Period Start | G13: Date | J13: =IF(J9 = 1, $F11, I14 + 1) -> 45658 | K13: =IF(K9 = 1, $F11, J14 + 1) -> 46023 | L13: =IF(L9 = 1, $F11, K14 + 1) -> 46388 | M13: =IF(M9 = 1, $F11, L14 + 1) -> 46753 | N13: =IF(N9 = 1, $F11, M14 + 1) -> 47119 | O13: =IF(O9 = 1, $F11, N14 + 1) -> 47484
E14: Period End | G14: Date | J14: =EOMONTH(J13, 11) -> 46022 | K14: =EOMONTH(K13, 11) -> 46387 | L14: =EOMONTH(L13, 11) -> 46752 | M14: =EOMONTH(M13, 11) -> 47118 | N14: =EOMONTH(N13, 11) -> 47483 | O14: =EOMONTH(O13, 11) -> 47848
E15: Number of Days | G15: Days | J15: =_xlfn.DAYS(J14, J13 ) + 1 -> 365 | K15: =_xlfn.DAYS(K14, K13 ) + 1 -> 365 | L15: =_xlfn.DAYS(L14, L13 ) + 1 -> 365 | M15: =_xlfn.DAYS(M14, M13 ) + 1 -> 366 | N15: =_xlfn.DAYS(N14, N13 ) + 1 -> 365 | O15: =_xlfn.DAYS(O14, O13 ) + 1 -> 365
E16: Financial Year | G16: Year | J16: =YEAR(J14) -> 2025 | K16: =YEAR(K14) -> 2026 | L16: =YEAR(L14) -> 2027 | M16: =YEAR(M14) -> 2028 | N16: =YEAR(N14) -> 2029 | O16: =YEAR(O14) -> 2030
B18: Actuals
E19: =InpC!E$13 -> Actual Start Date | F19: =InpC!F$13 -> 45658 | G19: =InpC!G$13 -> Date
E20: =InpC!E$14 -> Actual End Date | F20: =InpC!F$14 -> 46022 | G20: =InpC!G$14 -> Date
E21: Actuals Start | G21: Flag | H21: =SUM(J21:O21) -> 1 | J21: =IF(AND($F19>=J$13, $F19<=J$14), 1, 0) -> 1 | K21: =IF(AND($F19>=K$13, $F19<=K$14), 1, 0) -> 0 | L21: =IF(AND($F19>=L$13, $F19<=L$14), 1, 0) -> 0 | M21: =IF(AND($F19>=M$13, $F19<=M$14), 1, 0) -> 0 | N21: =IF(AND($F19>=N$13, $F19<=N$14), 1, 0) -> 0 | O21: =IF(AND($F19>=O$13, $F19<=O$14), 1, 0) -> 0
E22: Actuals End | G22: Flag | H22: =SUM(J22:O22) -> 1 | J22: =IF(AND($F20>=J$13, $F20<=J$14), 1, 0) -> 1 | K22: =IF(AND($F20>=K$13, $F20<=K$14), 1, 0) -> 0 | L22: =IF(AND($F20>=L$13, $F20<=L$14), 1, 0) -> 0 | M22: =IF(AND($F20>=M$13, $F20<=M$14), 1, 0) -> 0 | N22: =IF(AND($F20>=N$13, $F20<=N$14), 1, 0) -> 0 | O22: =IF(AND($F20>=O$13, $F20<=O$14), 1, 0) -> 0
E23: Actuals Active | G23: Flag | H23: =SUM(J23:O23) -> 1 | J23: =J21 +I23 - I22 -> 1 | K23: =K21 +J23 - J22 -> 0 | L23: =L21 +K23 - K22 -> 0 | M23: =M21 +L23 - L22 -> 0 | N23: =N21 +M23 - M22 -> 0 | O23: =O21 +N23 - N22 -> 0
B25: Projections
E26: =InpC!E$17 -> Projection Start Date | F26: =InpC!F$17 -> 46023 | G26: =InpC!G$17 -> Date
E27: =InpC!E$18 -> Projection End Date | F27: =InpC!F$18 -> 47848 | G27: =InpC!G$18 -> Date
E28: Projections Start | G28: Flag | H28: =SUM(J28:O28) -> 1 | J28: =IF(AND($F26>=J$13, $F26<=J$14), 1, 0) -> 0 | K28: =IF(AND($F26>=K$13, $F26<=K$14), 1, 0) -> 1 | L28: =IF(AND($F26>=L$13, $F26<=L$14), 1, 0) -> 0 | M28: =IF(AND($F26>=M$13, $F26<=M$14), 1, 0) -> 0 | N28: =IF(AND($F26>=N$13, $F26<=N$14), 1, 0) -> 0 | O28: =IF(AND($F26>=O$13, $F26<=O$14), 1, 0) -> 0
E29: Projections End | G29: Flag | H29: =SUM(J29:O29) -> 1 | J29: =IF(AND($F27>=J$13, $F27<=J$14), 1, 0) -> 0 | K29: =IF(AND($F27>=K$13, $F27<=K$14), 1, 0) -> 0 | L29: =IF(AND($F27>=L$13, $F27<=L$14), 1, 0) -> 0 | M29: =IF(AND($F27>=M$13, $F27<=M$14), 1, 0) -> 0 | N29: =IF(AND($F27>=N$13, $F27<=N$14), 1, 0) -> 0 | O29: =IF(AND($F27>=O$13, $F27<=O$14), 1, 0) -> 1
E30: Projections Active | G30: Flag | H30: =SUM(J30:O30) -> 5 | J30: =J28 +I30 - I29 -> 0 | K30: =K28 +J30 - J29 -> 1 | L30: =L28 +K30 - K29 -> 1 | M30: =M28 +L30 - L29 -> 1 | N30: =N28 +M30 - M29 -> 1 | O30: =O28 +N30 - N29 -> 1
E31: Projections Period | G31: Year | J31: =I31 + J30 -> 0 | K31: =J31 + K30 -> 1 | L31: =K31 + L30 -> 2 | M31: =L31 + M30 -> 3 | N31: =M31 + N30 -> 4 | O31: =N31 + O30 -> 5
A33: FINANCIAL STATEMENTS
B35: Income Statement
E36: =E$87 -> Revenue | F36: =F$87 -> 0 | G36: =G$87 -> INR Crs | H36: =H$87 -> 0 | I36: =I$87 -> 0 | J36: =J$87 -> 1200 | K36: =K$87 -> 1320 | L36: =L$87 -> 1452 | ... O36: =O$87 -> 1932.612
E37: Operating Expenses | G37: INR Crs | J37: =J36 - J38 -> 864 | K37: =K36 - K38 -> 937.2 | L37: =L36 - L38 -> 1016.4 | M37: =M36 - M38 -> 1118.04 | N37: =N36 - N38 -> 1229.844 | O37: =O36 - O38 -> 1352.8284
E38: =E$93 -> EBITDA | F38: =F$93 -> 0 | G38: =G$93 -> INR Crs | H38: =H$93 -> 0 | I38: =I$93 -> 0 | J38: =J$93 -> 336 | K38: =K$93 -> 382.8 | L38: =L$93 -> 435.6 | ... O38: =O$93 -> 579.7836
E40: =E$98 -> Depreciation | F40: =F$98 -> 0 | G40: =G$98 -> INR Crs | H40: =H$98 -> 0 | I40: =I$98 -> 0 | J40: =J$98 -> 60 | K40: =K$98 -> 66 | L40: =L$98 -> 72.6 | ... O40: =O$98 -> 96.6306
E41: EBIT | G41: INR Crs | J41: =J38 - J40 -> 276 | K41: =K38 - K40 -> 316.8 | L41: =L38 - L40 -> 363 | M41: =M38 - M40 -> 399.3 | N41: =N38 - N40 -> 439.23 | O41: =O38 - O40 -> 483.153
E43: =E$111 -> Interest Expense | F43: =F$111 -> 0 | G43: =G$111 -> INR Crs | H43: =H$111 -> 0 | I43: =I$111 -> 0 | J43: =J$111 -> 0 | K43: =K$111 -> 44 | L43: =L$111 -> 44 | ... O43: =O$111 -> 44
E44: Profit Before Tax | G44: INR Crs | J44: =J41 - J43 -> 276 | K44: =K41 - K43 -> 272.8 | L44: =L41 - L43 -> 319 | M44: =M41 - M43 -> 355.3 | N44: =N41 - N43 -> 395.23 | O44: =O41 - O43 -> 439.153
E46: =E$117 -> Tax Expense | F46: =F$117 -> 0 | G46: =G$117 -> INR Crs | H46: =H$117 -> 0 | I46: =I$117 -> 0 | J46: 96 | K46: =K$117 -> 68.2 | L46: =L$117 -> 79.75 | M46: =M$117 -> 88.825 | N46: =N$117 -> 98.8075 | O46: =O$117 -> 109.78825
E47: Profit After Tax | G47: INR Crs | J47: =J44 - J46 -> 180 | K47: =K44 - K46 -> 204.6 | L47: =L44 - L46 -> 239.25 | M47: =M44 - M46 -> 266.475 | N47: =N44 - N46 -> 296.4225 | O47: =O44 - O46 -> 329.36475
B49: Balance Sheet
C50: Assets
E51: Fixed Assets | G51: INR Crs | J51: 950 | K51: =K$129 -> 1016 | L51: =L$129 -> 1088.6 | M51: =M$129 -> 1168.46 | N51: =N$129 -> 1256.306 | O51: =O$129 -> 1352.9366
E52: Working Capital | G52: INR Crs | J52: 480 | K52: =J52 -> 480 | L52: =K52 -> 480 | M52: =L52 -> 480 | N52: =M52 -> 480 | O52: =N52 -> 480
...

Sheet Transaction_Workings
E1: =Beta!E$13 -> Period Start | F1: =Beta!F$13 -> 0 | G1: =Beta!G$13 -> Date | H1: =Beta!H$13 -> 0 | I1: =Beta!I$13 -> 0 | J1: =Beta!J$13 -> 45658 | K1: =Beta!K$13 -> 46023 | L1: =Beta!L$13 -> 46388 | ... O1: =Beta!O$13 -> 47484
E2: =Beta!E$14 -> Period End | F2: =Beta!F$14 -> 0 | G2: =Beta!G$14 -> Date | H2: =Beta!H$14 -> 0 | I2: =Beta!I$14 -> 0 | J2: =Beta!J$14 -> 46022 | K2: =Beta!K$14 -> 46387 | L2: =Beta!L$14 -> 46752 | ... O2: =Beta!O$14 -> 47848
E3: =Beta!E$15 -> Number of Days | F3: =Beta!F$15 -> 0 | G3: =Beta!G$15 -> Days | H3: =Beta!H$15 -> 0 | I3: =Beta!I$15 -> 0 | J3: =Beta!J$15 -> 365 | K3: =Beta!K$15 -> 365 | L3: =Beta!L$15 -> 365 | ... O3: =Beta!O$15 -> 365
E4: =Beta!E$16 -> Financial Year | F4: =Beta!F$16 -> 0 | G4: =Beta!G$16 -> Year | H4: =Beta!H$16 -> 0 | I4: =Beta!I$16 -> 0 | J4: =Beta!J$16 -> 2025 | K4: =Beta!K$16 -> 2026 | L4: =Beta!L$16 -> 2027 | ... O4: =Beta!O$16 -> 2030
F6: Constant | G6: Unit | H6: Total
A7: VALUATION
E9: =InpC!E$48 -> Corporate Tax Rate | F9: =InpC!F$48 -> 0.25 | G9: =InpC!G$48 -> %
E10: =InpC!E$50 -> WACC | F10: =InpC!F$50 -> 0.12 | G10: =InpC!G$50 -> %
E11: =InpC!E$51 -> Terminal Growth Rate | F11: =InpC!F$51 -> 0.04 | G11: =InpC!G$51 -> %
E12: =Beta!E$30 -> Projections Active | F12: =Beta!F$30 -> 0 | G12: =Beta!G$30 -> Flag | H12: =Beta!H$30 -> 5 | I12: =Beta!I$30 -> 0 | J12: =Beta!J$30 -> 0 | K12: =Beta!K$30 -> 1 | L12: =Beta!L$30 -> 1 | ... O12: =Beta!O$30 -> 1
E13: =Beta!E$29 -> Projections End | F13: =Beta!F$29 -> 0 | G13: =Beta!G$29 -> Flag | H13: =Beta!H$29 -> 1 | I13: =Beta!I$29 -> 0 | J13: =Beta!J$29 -> 0 | K13: =Beta!K$29 -> 0 | L13: =Beta!L$29 -> 0 | ... O13: =Beta!O$29 -> 1
E14: =Beta!E$31 -> Projections Period | F14: =Beta!F$31 -> 0 | G14: =Beta!G$31 -> Year | H14: =Beta!H$31 -> 0 | I14: =Beta!I$31 -> 0 | J14: =Beta!J$31 -> 0 | K14: =Beta!K$31 -> 1 | L14: =Beta!L$31 -> 2 | ... O14: =Beta!O$31 -> 5
E15: =Beta!E$41 -> EBIT | F15: =Beta!F$41 -> 0 | G15: =Beta!G$41 -> INR Crs | H15: =Beta!H$41 -> 0 | I15: =Beta!I$41 -> 0 | J15: =Beta!J$41 -> 276 | K15: =Beta!K$41 -> 316.8 | L15: =Beta!L$41 -> 363 | ... O15: =Beta!O$41 -> 483.153
E16: Taxes | G16: INR Crs | J16: =IF(J12=1, $F9 * J$15, 0) -> 0 | K16: =IF(K12=1, $F9 * K$15, 0) -> 79.2 | L16: =IF(L12=1, $F9 * L$15, 0) -> 90.75 | M16: =IF(M12=1, $F9 * M$15, 0) -> 99.825 | N16: =IF(N12=1, $F9 * N$15, 0) -> 109.8075 | O16: =IF(O12=1, $F9 * O$15, 0) -> 120.78825
E17: NOPAT | G17: INR Crs | J17: =IF(J12=1, J15-J16, 0) -> 0 | K17: =IF(K12=1, K15-K16, 0) -> 237.6 | L17: =IF(L12=1, L15-L16, 0) -> 272.25 | M17: =IF(M12=1, M15-M16, 0) -> 299.475 | N17: =IF(N12=1, N15-N16, 0) -> 329.4225 | O17: =IF(O12=1, O15-O16, 0) -> 362.36475
E18: =Beta!E$40 -> Depreciation | F18: =Beta!F$40 -> 0 | G18: =Beta!G$40 -> INR Crs | H18: =Beta!H$40 -> 0 | I18: =Beta!I$40 -> 0 | J18: =Beta!J$40 -> 60 | K18: =Beta!K$40 -> 66 | L18: =Beta!L$40 -> 72.6 | ... O18: =Beta!O$40 -> 96.6306
E19: =Beta!E$67 -> Changes in working capital | F19: =Beta!F$67 -> 0 | G19: =Beta!G$67 -> INR Crs | H19: =Beta!H$67 -> 0 | I19: =Beta!I$67 -> 0 | J19: =Beta!J$67 -> 0 | K19: =Beta!K$67 -> 0 | L19: =Beta!L$67 -> 0 | ... O19: =Beta!O$67 -> 0
E20: =Beta!E$70 -> Capital Expenditure | F20: =Beta!F$70 -> 0 | G20: =Beta!G$70 -> INR Crs | H20: =Beta!H$70 -> 0 | I20: =Beta!I$70 -> 0 | J20: =Beta!J$70 -> 0 | K20: =Beta!K$70 -> -132 | L20: =Beta!L$70 -> -145.2 | ... O20: =Beta!O$70 -> -193.2612
E21: Free Cash Flow to Firm/ Unlevered Cash Flows | G21: INR Crs | J21: =IF(J12=1,SUM(J17:J20), 0) -> 0 | K21: =IF(K12=1,SUM(K17:K20), 0) -> 171.6 | L21: =IF(L12=1,SUM(L17:L20), 0) -> 199.65 | M21: =IF(M12=1,SUM(M17:M20), 0) -> 219.615 | N21: =IF(N12=1,SUM(N17:N20), 0) -> 241.5765 | O21: =IF(O12=1,SUM(O17:O20), 0) -> 265.73415
E22: Terminal Value of FCFF | G22: INR Crs | J22: =IF(J13=1, (J21*(1+$F$11))/($F$10-$F$11), 0) -> 0 | K22: =IF(K13=1, (K21*(1+$F$11))/($F$10-$F$11), 0) -> 0 | L22: =IF(L13=1, (L21*(1+$F$11))/($F$10-$F$11), 0) -> 0 | M22: =IF(M13=1, (M21*(1+$F$11))/($F$10-$F$11), 0) -> 0 | N22: =IF(N13=1, (N21*(1+$F$11))/($F$10-$F$11), 0) -> 0 | O22: =IF(O13=1, (O21*(1+$F$11))/($F$10-$F$11), 0) -> 3454.544
E23: Total Cashflows to be discounted | G23: INR Crs | J23: =SUM(J21:J22) -> 0 | K23: =SUM(K21:K22) -> 171.6 | L23: =SUM(L21:L22) -> 199.65 | M23: =SUM(M21:M22) -> 219.615 | N23: =SUM(N21:N22) -> 241.5765 | O23: =SUM(O21:O22) -> 3720.2781
E24: Discounting Factor | G24: % | J24: =IF(J12=1, 1/(1+$F$10)^J14, 0) -> 0 | K24: =IF(K12=1, 1/(1+$F$10)^K14, 0) -> 0.89285714 | L24: =IF(L12=1, 1/(1+$F$10)^L14, 0) -> 0.79719388 | M24: =IF(M12=1, 1/(1+$F$10)^M14, 0) -> 0.71178025 | N24: =IF(N12=1, 1/(1+$F$10)^N14, 0) -> 0.63551808 | O24: =IF(O12=1, 1/(1+$F$10)^O14, 0) -> 0.56742686
E25: Discounted Cash Flows | G25: INR Crs | J25: =J23 * J24 -> 0 | K25: =K23 * K24 -> 153.21429 | L25: =L23 * L24 -> 159.15976 | M25: =M23 * M24 -> 156.31762 | N25: =N23 * N24 -> 153.52623 | O25: =O23 * O24 -> 2110.9857
E27: Enterprise Value of Beta Componenets | F27: =SUM(J25:O25) -> 2733.2036 | G27: INR Crs
E28: =InpC!E$56 -> Cash | F28: =InpC!F$56 -> 120 | G28: =InpC!G$56 -> INR Crs
E29: =InpC!E$60 -> Long-term Debt | F29: =InpC!F$60 -> 400 | G29: =InpC!G$60 -> INR Crs
E30: Equity Value of Beta Components | F30: =F27 +F28 - F29 -> 2453.2036 | G30: INR Crs
A32: RATIOS
C34: Enterprise Value to EBITDA
E35: =E$27 -> Enterprise Value of Beta Componenets | F35: =F$27 -> 2733.2036 | G35: =G$27 -> INR Crs
E36: EBITDA | F36: =Beta!J$38 -> 336 | G36: INR Crs
E37: EV/ EBITDA | F37: =F35 / F36 -> 8.1345345 | G37: Times
C39: Price to Earnings Ratio
E40: =E$30 -> Equity Value of Beta Components | F40: =F$30 -> 2453.2036 | G40: =G$30 -> INR Crs
E41: Profit Ater Tax | F41: =Beta!J$47 -> 180 | G41: INR Crs
E42: P/E Ratio | F42: =F40 / F41 -> 13.628909 | G42: Times
A44: TRANSACTION DETAILS
E46: =InpC!E$66 -> Transaction Date | F46: =InpC!F$66 -> 46023 | G46: =InpC!G$66 -> Date
E47: =InpC!E$67 -> Transaction Premium | F47: =InpC!F$67 -> 0.25 | G47: =InpC!G$67 -> %
E48: =E$30 -> Equity Value of Beta Components | F48: =F$30 -> 2453.2036 | G48: =G$30 -> INR Crs
...

Sheet Post_Merger
E1: =Alpha!E$13 -> Period Start | F1: =Alpha!F$13 -> 0 | G1: =Alpha!G$13 -> Date | H1: =Alpha!H$13 -> 0 | I1: =Alpha!I$13 -> 0 | J1: =Alpha!J$13 -> 45658 | K1: =Alpha!K$13 -> 46023 | L1: =Alpha!L$13 -> 46388 | ... O1: =Alpha!O$13 -> 47484
E2: =Alpha!E$14 -> Period End | F2: =Alpha!F$14 -> 0 | G2: =Alpha!G$14 -> Date | H2: =Alpha!H$14 -> 0 | I2: =Alpha!I$14 -> 0 | J2: =Alpha!J$14 -> 46022 | K2: =Alpha!K$14 -> 46387 | L2: =Alpha!L$14 -> 46752 | ... O2: =Alpha!O$14 -> 47848
E3: =Alpha!E$15 -> Number of Days | F3: =Alpha!F$15 -> 0 | G3: =Alpha!G$15 -> Days | H3: =Alpha!H$15 -> 0 | I3: =Alpha!I$15 -> 0 | J3: =Alpha!J$15 -> 365 | K3: =Alpha!K$15 -> 365 | L3: =Alpha!L$15 -> 365 | ... O3: =Alpha!O$15 -> 365
E4: =Alpha!E$16 -> Financial Year | F4: =Alpha!F$16 -> 0 | G4: =Alpha!G$16 -> Year | H4: =Alpha!H$16 -> 0 | I4: =Alpha!I$16 -> 0 | J4: =Alpha!J$16 -> 2025 | K4: =Alpha!K$16 -> 2026 | L4: =Alpha!L$16 -> 2027 | ... O4: =Alpha!O$16 -> 2030
F6: Constant | G6: Unit | H6: Total
A7: FINANCIAL STATEMENTS
B9: Income Statement
E10: =E$75 -> Total Revenue | F10: =F$75 -> 0 | G10: =G$75 -> INR Crs | H10: =H$75 -> 0 | I10: =I$75 -> 0 | J10: =J$75 -> 6200 | K10: =K$75 -> 6720 | L10: =L$75 -> 7284 | ... O10: =O$75 -> 9279.2524
E11: =E$86 -> Total Operational Expenditure Post- Synergies | F11: =F$86 -> 0 | G11: =G$86 -> INR Crs | H11: =H$86 -> 0 | I11: =I$86 -> 0 | J11: =J$86 -> 4764 | K11: =K$86 -> 5249.2 | L11: =L$86 -> 5485.36 | ... O11: =O$86 -> 7003.2079
E12: EBITDA | F12: 0 | G12: INR Crs | J12: =J10 - J11 -> 1436 | K12: =K10 - K11 -> 1470.8 | L12: =L10 - L11 -> 1798.64 | M12: =M10 - M11 -> 1944.8432 | N12: =N10 - N11 -> 2103.6139 | O12: =O10 - O11 -> 2276.0445
E14: =E$91 -> Depreciation | F14: =F$91 -> 0 | G14: =G$91 -> INR Crs | H14: =H$91 -> 0 | I14: =I$91 -> 0 | J14: =J$91 -> 186 | K14: =K$91 -> 201.6 | L14: =L$91 -> 218.52 | ... O14: =O$91 -> 278.37757
E15: EBIT | G15: INR Crs | J15: =J12 - J14 -> 1250 | K15: =K12 - K14 -> 1269.2 | L15: =L12 - L14 -> 1580.12 | M15: =M12 - M14 -> 1707.9704 | N15: =N12 - N14 -> 1846.8329 | O15: =O12 - O14 -> 1997.6669
E17: =E$102 -> Interest Expense | F17: =F$102 -> 0 | G17: =G$102 -> INR Crs | H17: =H$102 -> 0 | I17: =I$102 -> 0 | J17: =J$102 -> 0 | K17: =K$102 -> 423.8524 | L17: =L$102 -> 423.8524 | ... O17: =O$102 -> 390.8524
E18: Profit Before Tax | G18: INR Crs | J18: =J15 - J17 -> 1250 | K18: =K15 - K17 -> 845.3476 | L18: =L15 - L17 -> 1156.2676 | M18: =M15 - M17 -> 1295.118 | N18: =N15 - N17 -> 1444.9805 | O18: =O15 - O17 -> 1606.8145
E20: =E$107 -> Corporate Income Tax | F20: =F$107 -> 0 | G20: =G$107 -> INR Crs | H20: =H$107 -> 0 | I20: =I$107 -> 0 | J20: =J$107 -> 312.5 | K20: =K$107 -> 211.3369 | L20: =L$107 -> 289.0669 | ... O20: =O$107 -> 401.70363
E21: Profit After Tax | G21: INR Crs | J21: =J18-J20 -> 937.5 | K21: =K18-K20 -> 634.0107 | L21: =L18-L20 -> 867.2007 | M21: =M18-M20 -> 971.3385 | N21: =N18-N20 -> 1083.7354 | O21: =O18-O20 -> 1205.1109
B23: Pre- Transaction
E24: =Alpha!E$48 -> Shares Outstanding | F24: =Alpha!F$48 -> 0 | G24: =Alpha!G$48 -> Crores | H24: =Alpha!H$48 -> 0 | I24: =Alpha!I$48 -> 0 | J24: =Alpha!J$48 -> 100 | K24: =Alpha!K$48 -> 100 | L24: =Alpha!L$48 -> 100 | ... O24: =Alpha!O$48 -> 100
E25: =Alpha!E$49 -> Earnings Per Share | F25: =Alpha!F$49 -> 0 | G25: =Alpha!G$49 -> INR | H25: =Alpha!H$49 -> 0 | I25: =Alpha!I$49 -> 0 | J25: =Alpha!J$49 -> 6.5 | K25: =Alpha!K$49 -> 6.945 | L25: =Alpha!L$49 -> 7.5606 | ... O25: =Alpha!O$49 -> 9.7189625
B27: Pre- Transaction
E28: =Transaction_Workings!E$68 -> New Shares to be issued | F28: =Transaction_Workings!F$68 -> 9.4353985 | G28: =Transaction_Workings!G$68 -> Crores
E29: Shares Outstanding | G29: Crores | J29: =J24 -> 100 | K29: =J29+$F$28 -> 109.4354 | L29: =K29 -> 109.4354 | M29: =L29 -> 109.4354 | N29: =M29 -> 109.4354 | O29: =N29 -> 109.4354
E30: Earnings Per Share | G30: INR | J30: =J21/ J29 -> 9.375 | K30: =K21/ K29 -> 5.79347 | L30: =L21/ L29 -> 7.9243162 | M30: =M21/ M29 -> 8.8759078 | N30: =N21/ N29 -> 9.9029693 | O30: =O21/ O29 -> 11.012076
E32: Accretion/ Dilution Analysis - INR | K32: =K30 - K25 -> -1.15153 | L32: =L30 - L25 -> 0.36371622 | M32: =M30 - M25 -> 0.65045977 | N32: =N30 - N25 -> 0.95948542 | O32: =O30 - O25 -> 1.2931131
E33: Accretion/ Dilution Analysis - % | K33: =K32/ K25 -> -0.16580705 | L33: =L32/ L25 -> 0.048106793 | M33: =M32/ M25 -> 0.079078947 | N33: =N32/ N25 -> 0.10728318 | O33: =O32/ O25 -> 0.13305053
B35: Balance Sheet
C36: Assets
E37: Fixed Assets | G37: INR Crs | J37: =Transaction_Workings!M$77 -> 3419.335 | K37: =J37- K14 -> 3217.735 | L37: =K37- L14 -> 2999.215 | M37: =L37- M14 -> 2762.3422 | N37: =M37- N14 -> 2505.5612 | O37: =N37- O14 -> 2227.1836
E38: Working Capital | G38: INR Crs | J38: =Transaction_Workings!M$78 -> 1780 | K38: =J38 -> 1780 | L38: =K38 -> 1780 | M38: =L38 -> 1780 | N38: =M38 -> 1780 | O38: =N38 -> 1780
E39: Cash | G39: INR Crs | J39: =Transaction_Workings!M$79 -> 520 | K39: =K65 -> 1355.6107 | L39: =L65 -> 2341.3314 | M39: =M65 -> 3449.5427 | N39: =N65 -> 4690.059 | O39: =O65 -> 6073.5475
E40: Goodwill | G40: INR Crs | J40: =Transaction_Workings!M$80 -> 2366.5045 | K40: =J40 -> 2366.5045 | L40: =K40 -> 2366.5045 | M40: =L40 -> 2366.5045 | N40: =M40 -> 2366.5045 | O40: =N40 -> 2366.5045
E41: Total Assets | G41: INR Crs | J41: =SUM(J37:J40) -> 8085.8395 | K41: =SUM(K37:K40) -> 8719.8502 | L41: =SUM(L37:L40) -> 9487.0509 | M41: =SUM(M37:M40) -> 10358.389 | N41: =SUM(N37:N40) -> 11342.125 | O41: =SUM(O37:O40) -> 12447.236
C43: Liabilities
E44: Equity (Net Worth) | G44: INR Crs | J44: =Transaction_Workings!M$83 -> 2782.6359 | K44: =J44 + K21 -> 3416.6466 | L44: =K44 + L21 -> 4283.8473 | M44: =L44 + M21 -> 5255.1858 | N44: =M44 + N21 -> 6338.9212 | O44: =N44 + O21 -> 7544.032
E45: Long-term Debt | G45: INR Crs | J45: =Transaction_Workings!M$84 -> 3853.2036 | K45: =K$100 -> 3853.2036 | L45: =L$100 -> 3753.2036 | M45: =M$100 -> 3653.2036 | N45: =N$100 -> 3553.2036 | O45: =O$100 -> 3453.2036
E46: Other Liabilities | G46: INR Crs | J46: =Transaction_Workings!M$85 -> 1450 | K46: =J46 -> 1450 | L46: =K46 -> 1450 | M46: =L46 -> 1450 | N46: =M46 -> 1450 | O46: =N46 -> 1450
E47: Total Liabilities | G47: INR Crs | J47: =SUM(J44:J46) -> 8085.8395 | K47: =SUM(K44:K46) -> 8719.8502 | L47: =SUM(L44:L46) -> 9487.0509 | M47: =SUM(M44:M46) -> 10358.389 | N47: =SUM(N44:N46) -> 11342.125 | O47: =SUM(O44:O46) -> 12447.236
E49: Balance sheet - Check | K49: =ROUND(J41 - J47, 2) -> 0 | L49: =ROUND(L41 - L47, 2) -> 0 | M49: =ROUND(M41 - M47, 2) -> 0 | N49: =ROUND(N41 - N47, 2) -> 0 | O49: =ROUND(O41 - O47, 2) -> 0
B51: Cash Flow Statement
E52: Profit After Tax | F52: 0 | G52: INR Crs | K52: =K21 -> 634.0107 | L52: =L21 -> 867.2007 | M52: =M21 -> 971.3385 | N52: =N21 -> 1083.7354 | O52: =O21 -> 1205.1109
...

Sheet Temp
F6: Constant | G6: Unit | H6: Total
